Workbook

Sheet Resumen
A1: Mosaicca · Proyección a 12 meses (nov 2026 a oct 2027)
A2: Estimación por escenarios con supuestos editables. No hay historial de ventas ni costos reales en el proyecto: sustituye las celdas amarillas de Supuestos y Costos antes de decidir inversiones.
A4: Concepto (MXN) | B4: Conservador | C4: Base | D4: Optimista | E4: Nota
A5: Pedidos totales en 12 meses | B5: =Demanda!N15+Demanda!N20 -> 327.19829 | C5: =Demanda!N35+Demanda!N40 -> 751.35 | D5: =Demanda!N55+Demanda!N60 -> 1610.3929 | E5: Minoristas más mayoreo.
A6: Cuentas mayoristas activas al cierre | B6: =Demanda!N19 -> 6.5132156 | C6: =Demanda!N39 -> 14.743363 | D6: =Demanda!N59 -> 32.101045
A7: Ventas netas (sin IVA) | B7: =Resultados!N8 -> 111366.22 | C7: =Resultados!N32 -> 335239.36 | D7: =Resultados!N56 -> 931959.85
A8: Costo de producción | B8: =Resultados!N9+Resultados!N10 -> 88113.493 | C8: =Resultados!N33+Resultados!N34 -> 242793.75 | D8: =Resultados!N57+Resultados!N58 -> 631824.61
A9: UTILIDAD BRUTA | B9: =Resultados!N11 -> 23252.73 | C9: =Resultados!N35 -> 92445.608 | D9: =Resultados!N59 -> 300135.24
A10: Margen bruto | B10: =Resultados!N12 -> 0.20879517 | C10: =Resultados!N36 -> 0.27576001 | D10: =Resultados!N60 -> 0.32204739
A11: Anuncios, comisiones, gastos fijos y depreciación | B11: =Resultados!N13+Resultados!N14+Resultados!N15+Resultados!N16 -> 142677.56 | C11: =Resultados!N37+Resultados!N38+Resultados!N39+Resultados!N40 -> 173433.63 | D11: =Resultados!N61+Resultados!N62+Resultados!N63+Resultados!N64 -> 225687.11
A12: UTILIDAD OPERATIVA (antes de impuestos) | B12: =Resultados!N17 -> -119424.83 | C12: =Resultados!N41 -> -80988.025 | D12: =Resultados!N65 -> 74448.125
A13: ISR · RESICO persona física | B13: =Resultados!N18 -> 1113.6622 | C13: =Resultados!N42 -> 3585.6235 | D13: =Resultados!N66 -> 16245.364 | E13: 1.0% a 2.5% sobre ingresos cobrados; aplica hasta $3.5 millones al año.
A14: UTILIDAD NETA · RESICO | B14: =Resultados!N19 -> -120538.5 | C14: =Resultados!N43 -> -84573.649 | D14: =Resultados!N67 -> 58202.762
A15: UTILIDAD NETA · persona moral (30% ISR + 10% PTU) | B15: =Resultados!N22 -> -119424.83 | C15: =Resultados!N46 -> -80988.025 | D15: =Resultados!N70 -> 43466.352 | E15: Alternativa si operas como persona moral con trabajadores.
A16: Límite RESICO | B16: =Resultados!N23 -> Dentro del límite | C16: =Resultados!N47 -> Dentro del límite | D16: =Resultados!N71 -> Dentro del límite
A17: Ventas netas necesarias para no perder (punto de equilibrio) | B17: =IFERROR((Resultados!N14+Resultados!N15+Resultados!N16)/Resultados!N12,0) -> 664127.74 | C17: =IFERROR((Resultados!N38+Resultados!N39+Resultados!N40)/Resultados!N36,0) -> 589884.91 | D17: =IFERROR((Resultados!N62+Resultados!N63+Resultados!N64)/Resultados!N60,0) -> 616886.44 | E17: Anuncios + gastos fijos + depreciación, divididos entre el margen bruto.
A18: Inversión: equipo e inicial | B18: =Inversión!D13 -> 56000 | C18: =Inversión!E13 -> 56000 | D18: =Inversión!F13 -> 56000
A19: Inversión: capital de trabajo | B19: =Inversión!D14 -> 35354.065 | C19: =Inversión!E14 -> 66260.119 | D19: =Inversión!F14 -> 139807.51
A20: INVERSIÓN TOTAL NECESARIA | B20: =Inversión!D15 -> 91354.065 | C20: =Inversión!E15 -> 122260.12 | D20: =Inversión!F15 -> 195807.51
A21: Recuperación de la inversión (meses) | B21: =Inversión!D17 -> No se recupera | C21: =Inversión!E17 -> No se recupera | D21: =Inversión!F17 -> 40.370767 | E21: Con la utilidad neta RESICO.
A23: Qué producir en el año (unidades)
A24: Producto | B24: Conservador | C24: Base | D24: Optimista | E24: Decisión de producción
A25: =Costos!A5 -> Fichas de lotería sueltas | B25: =ROUNDUP(Costos!Q5,0) -> 1293 | C25: =ROUNDUP(Costos!R5,0) -> 4095 | D25: =ROUNDUP(Costos!S5,0) -> 11839 | E25: =Costos!M5 -> Producir
A26: =Costos!A6 -> Paquete de 25 fichas | B26: =ROUNDUP(Costos!Q6,0) -> 308 | C26: =ROUNDUP(Costos!R6,0) -> 1049 | D26: =ROUNDUP(Costos!S6,0) -> 3191 | E26: =Costos!M6 -> Producir
A27: =Costos!A7 -> Paquete de 50 fichas | B27: =ROUNDUP(Costos!Q7,0) -> 136 | C27: =ROUNDUP(Costos!R7,0) -> 457 | D27: =ROUNDUP(Costos!S7,0) -> 1378 | E27: =Costos!M7 -> Producir
A28: =Costos!A8 -> Paquete de 100 fichas | B28: =ROUNDUP(Costos!Q8,0) -> 50 | C28: =ROUNDUP(Costos!R8,0) -> 168 | D28: =ROUNDUP(Costos!S8,0) -> 505 | E28: =Costos!M8 -> Producir
A29: =Costos!A9 -> Tazas personalizadas | B29: =ROUNDUP(Costos!Q9,0) -> 48 | C29: =ROUNDUP(Costos!R9,0) -> 135 | D29: =ROUNDUP(Costos!S9,0) -> 355 | E29: =Costos!M9 -> Tercerizar
A30: =Costos!A10 -> Vasos y termos personalizados | B30: =ROUNDUP(Costos!Q10,0) -> 23 | C30: =ROUNDUP(Costos!R10,0) -> 62 | D30: =ROUNDUP(Costos!S10,0) -> 159 | E30: =Costos!M10 -> Tercerizar
A31: =Costos!A11 -> Agendas | B31: =ROUNDUP(Costos!Q11,0) -> 25 | C31: =ROUNDUP(Costos!R11,0) -> 72 | D31: =ROUNDUP(Costos!S11,0) -> 192 | E31: =Costos!M11 -> Producir
A32: =Costos!A12 -> Libretas | B32: =ROUNDUP(Costos!Q12,0) -> 36 | C32: =ROUNDUP(Costos!R12,0) -> 115 | D32: =ROUNDUP(Costos!S12,0) -> 339 | E32: =Costos!M12 -> Producir
A33: =Costos!A13 -> Sellos (madera, autoentintables y cera) | B33: =ROUNDUP(Costos!Q13,0) -> 31 | C33: =ROUNDUP(Costos!R13,0) -> 96 | D33: =ROUNDUP(Costos!S13,0) -> 268 | E33: =Costos!M13 -> Tercerizar
A34: =Costos!A14 -> Impresión 3D y otros personalizados | B34: =ROUNDUP(Costos!Q14,0) -> 8 | C34: =ROUNDUP(Costos!R14,0) -> 20 | D34: =ROUNDUP(Costos!S14,0) -> 49 | E34: =Costos!M14 -> Producir
A35: =Costos!A15 -> Mini CD con NFC | B35: =ROUNDUP(Costos!Q15,0) -> 49 | C35: =ROUNDUP(Costos!R15,0) -> 152 | D35: =ROUNDUP(Costos!S15,0) -> 432 | E35: =Costos!M15 -> Producir
A36: =Costos!A16 -> Colección Pride | B36: =ROUNDUP(Costos!Q16,0) -> 29 | C36: =ROUNDUP(Costos!R16,0) -> 87 | D36: =ROUNDUP(Costos!S16,0) -> 248 | E36: =Costos!M16 -> Tercerizar
A37: =Costos!A17 -> Kits y regalos de temporada | B37: =ROUNDUP(Costos!Q17,0) -> 11 | C37: =ROUNDUP(Costos!R17,0) -> 30 | D37: =ROUNDUP(Costos!S17,0) -> 78 | E37: =Costos!M17 -> Producir
A39: Piezas de ficha a fabricar (sueltas y dentro de paquetes), caso base | C39: =Costos!R5+Costos!R6*25+Costos!R7*50+Costos!R8*100 -> 69911.347
A40: Kilos de filamento PLA al año, caso base | C40: =(Costos!R5*Costos!E5+Costos!R6*Costos!E6+Costos!R7*Costos!E7+Costos!R8*Costos!E8)/1000 -> 209.73404
A42: Cómo leer esto
A43: 1. Los costos de producción son de referencia. Solo el precio del filamento ($349 por kilo) tiene fuente. Pesa tus fichas, mide tus minutos de trabajo y pide cotizaciones; el resultado cambia mucho.
A44: 2. Revisa la hoja Costos: si un producto tiene margen negativo a precio de mayoreo, la página de mayoreo lo vende por debajo de tu costo. Ajusta descuentos por producto antes de activarla.
...

Sheet Supuestos
A1: Supuestos · proyección de 12 meses (nov 2026 a oct 2027)
A2: Azul = dato editable. Amarillo = lo que más mueve el resultado. No tengo tus ventas ni tus costos reales: todo lo marcado como supuesto debe reemplazarse con tus datos o cotizaciones.
A4: Demanda minorista | B4: Unidad | C4: Conservador | D4: Base | E4: Optimista | F4: Fuente o nota
A5: Pedidos orgánicos por semana al inicio (nov 2026) | B5: pedidos | C5: 5 | D5: 9 | E5: 14 | F5: SUPUESTO. Cámbialo por tus pedidos semanales reales (WhatsApp, Instagram y tienda).
A6: Crecimiento mensual de pedidos orgánicos | B6: % | C6: 0.01 | D6: 0.03 | E6: 0.05 | F6: SUPUESTO. Efecto de audiencia, reseñas y recompra.
A7: Inversión mensual en anuncios | B7: MXN | C7: 4000 | D7: 6000 | E7: 9000 | F7: Base = $200 al día, como en la campaña de Facebook.
A8: CPM (costo por mil impresiones) | B8: MXN | C8: 110 | D8: 85 | E8: 70 | F8: SUPUESTO. Sustituye con el CPM real de tu cuenta.
A9: CTR de enlace | B9: % | C9: 0.008 | D9: 0.012 | E9: 0.016 | F9: SUPUESTO.
A10: Clic → pedido (tienda y WhatsApp) | B10: % | C10: 0.01 | D10: 0.015 | E10: 0.022 | F10: SUPUESTO para tráfico frío de una tienda pequeña.
A11: Ticket promedio minorista (con IVA) | B11: MXN | C11: 320 | D11: 380 | E11: 450 | F11: SUPUESTO.
A13: Mayoreo | B13: Unidad | C13: Conservador | D13: Base | E13: Optimista | F13: Fuente o nota
A14: Cuentas mayoristas nuevas por mes | B14: cuentas | C14: 1 | D14: 2 | E14: 4 | F14: SUPUESTO. Depende de cuántos negocios contactes (ver Plan de mayoreo).
A15: Retención mensual de cuentas | B15: % | C15: 0.9 | D15: 0.93 | E15: 0.95 | F15: SUPUESTO.
A16: Pedidos por cuenta activa al mes | B16: pedidos | C16: 0.35 | D16: 0.5 | E16: 0.6 | F16: SUPUESTO: una recompra cada 2 meses en el caso base.
A17: Pedido promedio de mayoreo (sin IVA) | B17: MXN | C17: 1800 | D17: 2400 | E17: 3200 | F17: SUPUESTO. El mínimo es $1,500 a precio público.
A18: Factor de costos (sensibilidad) | B18: x | C18: 1.15 | D18: 1 | E18: 0.9 | F18: Multiplica todos los costos de producción: 1.15 = cuestan 15% más de lo estimado.
A20: Parámetros generales (un solo valor) | B20: Unidad | C20: Valor | F20: Fuente o nota
A21: Mes en que inicia el mayoreo (1 = nov 2026) | B21: mes | C21: 3 | F21: SUPUESTO: activar la página y contactar prospectos toma 2 meses.
A22: Descuento promedio de mayoreo | B22: % | C22: 0.42 | F22: Promedio de los tramos de 40%, 45% y 50% de la página de mayoreo.
A23: Tasa de IVA | B23: % | C23: 0.16 | F23: Ley del IVA.
A24: Precios públicos incluyen IVA (1 = sí, 0 = no) | B24: 1/0 | C24: 1 | F24: SUPUESTO. Confirma con tu contador. Los precios de mayoreo se tratan como «más IVA».
A25: Comisión de pasarela o marketplace sobre ventas minoristas | B25: % | C25: 0.04 | F25: SUPUESTO. Revisa la tarifa vigente de Mercado Pago o Conekta.
A26: Gastos fijos mensuales (espacio, luz, contador, hosting, software) | B26: MXN | C26: 6000 | F26: SUPUESTO. No incluye tu sueldo.
A27: Años de depreciación del equipo | B27: años | C27: 3 | F27: SUPUESTO.
A28: Meses de capital de trabajo | B28: meses | C28: 2 | F28: SUPUESTO: caja para cubrir 2 meses de costos de operación.
A29: ISR de persona moral | B29: % | C29: 0.3 | F29: Tasa general de la Ley del ISR (no la pude verificar en las búsquedas; confirma con tu contador).
A30: PTU | B30: % | C30: 0.1 | F30: Reparto de utilidades de 10% (no lo pude verificar; aplica solo si tienes trabajadores).
A31: Costo del filamento PLA | B31: MXN/kg | C31: 349 | F31: Creality México, PLA 1.75 mm de 1 kg: MX$349 (tienda en línea, oct 2026). Por volumen puede bajar.
A32: Flete y merma sobre producto tercerizado | B32: % | C32: 0.05 | F32: SUPUESTO.
... A36: Margen mínimo deseado sobre el precio de mayoreo | B36: % | C36: 0.25 | F36: SUPUESTO. Sirve para calcular el descuento máximo de mayoreo por producto (hoja Costos, última columna).
A37: Estacionalidad mensual | C37: Factor ventas | D37: Factor CPM | F37: Nota
A38: Nov 2026 | C38: 1.2 | D38: 1.15 | F38: Buen Fin y Día de Muertos. SUPUESTO de estacionalidad.
A39: Dic 2026 | C39: 1.7 | D39: 1.25 | F39: Navidad, posadas y aguinaldo
A40: Ene 2027 | C40: 0.7 | D40: 0.95 | F40: Cuesta de enero
A41: Feb 2027 | C41: 0.95 | D41: 1 | F41: 14 de febrero
A42: Mar 2027 | C42: 0.85 | D42: 1
A43: Abr 2027 | C43: 0.9 | D43: 1
A44: May 2027 | C44: 1.15 | D44: 1.05 | F44: Día de las Madres y del Maestro
A45: Jun 2027 | C45: 1 | D45: 1 | F45: Colección Pride
A46: Jul 2027 | C46: 0.8 | D46: 0.95 | F46: Vacaciones de verano
...

Sheet Demanda
A1: Demanda e ingresos por mes y escenario
A2: Anuncios: inversión ÷ CPM → clics → pedidos. Más pedidos orgánicos con crecimiento y estacionalidad. Más mayoreo: cuentas activas × pedidos × pedido promedio.
A4: ESCENARIO CONSERVADOR
A5: Concepto | B5: Nov 2026 | C5: Dic 2026 | D5: Ene 2027 | E5: Feb 2027 | F5: Mar 2027 | G5: Abr 2027 | H5: May 2027 | I5: Jun 2027 | J5: Jul 2027 | K5: Ago 2027 | L5: Sep 2027 | M5: Oct 2027 | N5: Total 12 meses
A6: Número de mes | B6: 1 | C6: 2 | D6: 3 | E6: 4 | F6: 5 | G6: 6 | H6: 7 | I6: 8 | J6: 9 | K6: 10 | L6: 11 | M6: 12
A7: Factor estacional de ventas | B7: =Supuestos!$C$38 -> 1.2 | C7: =Supuestos!$C$39 -> 1.7 | D7: =Supuestos!$C$40 -> 0.7 | E7: =Supuestos!$C$41 -> 0.95 | F7: =Supuestos!$C$42 -> 0.85 | G7: =Supuestos!$C$43 -> 0.9 | H7: =Supuestos!$C$44 -> 1.15 | I7: =Supuestos!$C$45 -> 1 | J7: =Supuestos!$C$46 -> 0.8 | K7: =Supuestos!$C$47 -> 0.9 | L7: =Supuestos!$C$48 -> 1 | M7: =Supuestos!$C$49 -> 1.05
A8: Factor estacional de CPM | B8: =Supuestos!$D$38 -> 1.15 | C8: =Supuestos!$D$39 -> 1.25 | D8: =Supuestos!$D$40 -> 0.95 | E8: =Supuestos!$D$41 -> 1 | F8: =Supuestos!$D$42 -> 1 | G8: =Supuestos!$D$43 -> 1 | H8: =Supuestos!$D$44 -> 1.05 | I8: =Supuestos!$D$45 -> 1 | J8: =Supuestos!$D$46 -> 0.95 | K8: =Supuestos!$D$47 -> 1 | L8: =Supuestos!$D$48 -> 1 | M8: =Supuestos!$D$49 -> 1.05
A9: Inversión en anuncios (MXN) | B9: =Supuestos!$C$7 -> 4000 | C9: =Supuestos!$C$7 -> 4000 | D9: =Supuestos!$C$7 -> 4000 | E9: =Supuestos!$C$7 -> 4000 | F9: =Supuestos!$C$7 -> 4000 | G9: =Supuestos!$C$7 -> 4000 | H9: =Supuestos!$C$7 -> 4000 | I9: =Supuestos!$C$7 -> 4000 | ... M9: =Supuestos!$C$7 -> 4000 | N9: =SUM(B9:M9) -> 48000
A10: Impresiones | B10: =B9/(Supuestos!$C$8*B8)*1000 -> 31620.553 | C10: =C9/(Supuestos!$C$8*C8)*1000 -> 29090.909 | D10: =D9/(Supuestos!$C$8*D8)*1000 -> 38277.512 | E10: =E9/(Supuestos!$C$8*E8)*1000 -> 36363.636 | F10: =F9/(Supuestos!$C$8*F8)*1000 -> 36363.636 | G10: =G9/(Supuestos!$C$8*G8)*1000 -> 36363.636 | H10: =H9/(Supuestos!$C$8*H8)*1000 -> 34632.035 | I10: =I9/(Supuestos!$C$8*I8)*1000 -> 36363.636 | ... M10: =M9/(Supuestos!$C$8*M8)*1000 -> 34632.035 | N10: =SUM(B10:M10) -> 424712.37
A11: Clics | B11: =B10*Supuestos!$C$9 -> 252.96443 | C11: =C10*Supuestos!$C$9 -> 232.72727 | D11: =D10*Supuestos!$C$9 -> 306.2201 | E11: =E10*Supuestos!$C$9 -> 290.90909 | F11: =F10*Supuestos!$C$9 -> 290.90909 | G11: =G10*Supuestos!$C$9 -> 290.90909 | H11: =H10*Supuestos!$C$9 -> 277.05628 | I11: =I10*Supuestos!$C$9 -> 290.90909 | ... M11: =M10*Supuestos!$C$9 -> 277.05628 | N11: =SUM(B11:M11) -> 3397.699
A12: Conversión efectiva | B12: =Supuestos!$C$10*B7 -> 0.012 | C12: =Supuestos!$C$10*C7 -> 0.017 | D12: =Supuestos!$C$10*D7 -> 0.007 | E12: =Supuestos!$C$10*E7 -> 0.0095 | F12: =Supuestos!$C$10*F7 -> 0.0085 | G12: =Supuestos!$C$10*G7 -> 0.009 | H12: =Supuestos!$C$10*H7 -> 0.0115 | I12: =Supuestos!$C$10*I7 -> 0.01 | ... M12: =Supuestos!$C$10*M7 -> 0.0105
A13: Pedidos por anuncios | B13: =B11*B12 -> 3.0355731 | C13: =C11*C12 -> 3.9563636 | D13: =D11*D12 -> 2.1435407 | E13: =E11*E12 -> 2.7636364 | F13: =F11*F12 -> 2.4727273 | G13: =G11*G12 -> 2.6181818 | H13: =H11*H12 -> 3.1861472 | I13: =I11*I12 -> 2.9090909 | ... M13: =M11*M12 -> 2.9090909 | N13: =SUM(B13:M13) -> 33.971385
A14: Pedidos orgánicos | B14: =Supuestos!$C$5*4.345*(1+Supuestos!$C$6)^(B6-1)*B7 -> 26.07 | C14: =Supuestos!$C$5*4.345*(1+Supuestos!$C$6)^(C6-1)*C7 -> 37.301825 | D14: =Supuestos!$C$5*4.345*(1+Supuestos!$C$6)^(D6-1)*D7 -> 15.513171 | E14: =Supuestos!$C$5*4.345*(1+Supuestos!$C$6)^(E6-1)*E7 -> 21.264125 | F14: =Supuestos!$C$5*4.345*(1+Supuestos!$C$6)^(F6-1)*F7 -> 19.216054 | G14: =Supuestos!$C$5*4.345*(1+Supuestos!$C$6)^(G6-1)*G7 -> 20.549874 | H14: =Supuestos!$C$5*4.345*(1+Supuestos!$C$6)^(H6-1)*H7 -> 26.520754 | I14: =Supuestos!$C$5*4.345*(1+Supuestos!$C$6)^(I6-1)*I7 -> 23.292141 | ... M14: =Supuestos!$C$5*4.345*(1+Supuestos!$C$6)^(M6-1)*M7 -> 25.44979 | N14: =SUM(B14:M14) -> 279.37998
A15: Pedidos minoristas totales | B15: =B13+B14 -> 29.105573 | C15: =C13+C14 -> 41.258189 | D15: =D13+D14 -> 17.656711 | E15: =E13+E14 -> 24.027761 | F15: =F13+F14 -> 21.688781 | G15: =G13+G14 -> 23.168056 | H15: =H13+H14 -> 29.706901 | I15: =I13+I14 -> 26.201231 | ... M15: =M13+M14 -> 28.35888 | N15: =SUM(B15:M15) -> 313.35136
A16: Ventas minoristas con IVA (MXN) | B16: =B15*Supuestos!$C$11 -> 9313.7834 | C16: =C15*Supuestos!$C$11 -> 13202.62 | D16: =D15*Supuestos!$C$11 -> 5650.1477 | E16: =E15*Supuestos!$C$11 -> 7688.8836 | F16: =F15*Supuestos!$C$11 -> 6940.4099 | G16: =G15*Supuestos!$C$11 -> 7413.7779 | H16: =H15*Supuestos!$C$11 -> 9506.2084 | I16: =I15*Supuestos!$C$11 -> 8384.3941 | ... M16: =M15*Supuestos!$C$11 -> 9074.8418 | N16: =SUM(B16:M16) -> 100272.44
A17: Ventas minoristas netas, sin IVA (MXN) | B17: =B16/(1+Supuestos!$C$23*Supuestos!$C$24) -> 8029.1236 | C17: =C16/(1+Supuestos!$C$23*Supuestos!$C$24) -> 11381.569 | D17: =D16/(1+Supuestos!$C$23*Supuestos!$C$24) -> 4870.8169 | E17: =E16/(1+Supuestos!$C$23*Supuestos!$C$24) -> 6628.3479 | F17: =F16/(1+Supuestos!$C$23*Supuestos!$C$24) -> 5983.112 | G17: =G16/(1+Supuestos!$C$23*Supuestos!$C$24) -> 6391.1878 | H17: =H16/(1+Supuestos!$C$23*Supuestos!$C$24) -> 8195.0072 | I17: =I16/(1+Supuestos!$C$23*Supuestos!$C$24) -> 7227.9259 | ... M17: =M16/(1+Supuestos!$C$23*Supuestos!$C$24) -> 7823.1394 | N17: =SUM(B17:M17) -> 86441.756
A18: Cuentas mayoristas nuevas | B18: =IF(B6>=Supuestos!$C$21,Supuestos!$C$14,0) -> 0 | C18: =IF(C6>=Supuestos!$C$21,Supuestos!$C$14,0) -> 0 | D18: =IF(D6>=Supuestos!$C$21,Supuestos!$C$14,0) -> 1 | E18: =IF(E6>=Supuestos!$C$21,Supuestos!$C$14,0) -> 1 | F18: =IF(F6>=Supuestos!$C$21,Supuestos!$C$14,0) -> 1 | G18: =IF(G6>=Supuestos!$C$21,Supuestos!$C$14,0) -> 1 | H18: =IF(H6>=Supuestos!$C$21,Supuestos!$C$14,0) -> 1 | I18: =IF(I6>=Supuestos!$C$21,Supuestos!$C$14,0) -> 1 | ... M18: =IF(M6>=Supuestos!$C$21,Supuestos!$C$14,0) -> 1 | N18: =SUM(B18:M18) -> 10
A19: Cuentas mayoristas activas | B19: =B18 -> 0 | C19: =B19*Supuestos!$C$15+C18 -> 0 | D19: =C19*Supuestos!$C$15+D18 -> 1 | E19: =D19*Supuestos!$C$15+E18 -> 1.9 | F19: =E19*Supuestos!$C$15+F18 -> 2.71 | G19: =F19*Supuestos!$C$15+G18 -> 3.439 | H19: =G19*Supuestos!$C$15+H18 -> 4.0951 | I19: =H19*Supuestos!$C$15+I18 -> 4.68559 | J19: =I19*Supuestos!$C$15+J18 -> 5.217031 | ... M19: =L19*Supuestos!$C$15+M18 -> 6.5132156 | N19: =M19 -> 6.5132156
A20: Pedidos de mayoreo | B20: =B19*Supuestos!$C$16*B7 -> 0 | C20: =C19*Supuestos!$C$16*C7 -> 0 | D20: =D19*Supuestos!$C$16*D7 -> 0.245 | E20: =E19*Supuestos!$C$16*E7 -> 0.63175 | F20: =F19*Supuestos!$C$16*F7 -> 0.806225 | G20: =G19*Supuestos!$C$16*G7 -> 1.083285 | H20: =H19*Supuestos!$C$16*H7 -> 1.6482778 | I20: =I19*Supuestos!$C$16*I7 -> 1.6399565 | ... M20: =M19*Supuestos!$C$16*M7 -> 2.3936067 | N20: =SUM(B20:M20) -> 13.846926
A21: Ventas de mayoreo, sin IVA (MXN) | B21: =B20*Supuestos!$C$17 -> 0 | C21: =C20*Supuestos!$C$17 -> 0 | D21: =D20*Supuestos!$C$17 -> 441 | E21: =E20*Supuestos!$C$17 -> 1137.15 | F21: =F20*Supuestos!$C$17 -> 1451.205 | G21: =G20*Supuestos!$C$17 -> 1949.913 | H21: =H20*Supuestos!$C$17 -> 2966.8999 | I21: =I20*Supuestos!$C$17 -> 2951.9217 | ... M21: =M20*Supuestos!$C$17 -> 4308.4921 | N21: =SUM(B21:M21) -> 24924.467
A22: VENTAS NETAS TOTALES (MXN) | B22: =B17+B21 -> 8029.1236 | C22: =C17+C21 -> 11381.569 | D22: =D17+D21 -> 5311.8169 | E22: =E17+E21 -> 7765.4979 | F22: =F17+F21 -> 7434.317 | G22: =G17+G21 -> 8341.1008 | H22: =H17+H21 -> 11161.907 | I22: =I17+I21 -> 10179.848 | ... M22: =M17+M21 -> 12131.632 | N22: =SUM(B22:M22) -> 111366.22
A24: ESCENARIO BASE
A25: Concepto | B25: Nov 2026 | C25: Dic 2026 | D25: Ene 2027 | E25: Feb 2027 | F25: Mar 2027 | G25: Abr 2027 | H25: May 2027 | I25: Jun 2027 | J25: Jul 2027 | K25: Ago 2027 | L25: Sep 2027 | M25: Oct 2027 | N25: Total 12 meses
A26: Número de mes | B26: 1 | C26: 2 | D26: 3 | E26: 4 | F26: 5 | G26: 6 | H26: 7 | I26: 8 | J26: 9 | K26: 10 | L26: 11 | M26: 12
A27: Factor estacional de ventas | B27: =Supuestos!$C$38 -> 1.2 | C27: =Supuestos!$C$39 -> 1.7 | D27: =Supuestos!$C$40 -> 0.7 | E27: =Supuestos!$C$41 -> 0.95 | F27: =Supuestos!$C$42 -> 0.85 | G27: =Supuestos!$C$43 -> 0.9 | H27: =Supuestos!$C$44 -> 1.15 | I27: =Supuestos!$C$45 -> 1 | J27: =Supuestos!$C$46 -> 0.8 | K27: =Supuestos!$C$47 -> 0.9 | L27: =Supuestos!$C$48 -> 1 | M27: =Supuestos!$C$49 -> 1.05
A28: Factor estacional de CPM | B28: =Supuestos!$D$38 -> 1.15 | C28: =Supuestos!$D$39 -> 1.25 | D28: =Supuestos!$D$40 -> 0.95 | E28: =Supuestos!$D$41 -> 1 | F28: =Supuestos!$D$42 -> 1 | G28: =Supuestos!$D$43 -> 1 | H28: =Supuestos!$D$44 -> 1.05 | I28: =Supuestos!$D$45 -> 1 | J28: =Supuestos!$D$46 -> 0.95 | K28: =Supuestos!$D$47 -> 1 | L28: =Supuestos!$D$48 -> 1 | M28: =Supuestos!$D$49 -> 1.05
A29: Inversión en anuncios (MXN) | B29: =Supuestos!$D$7 -> 6000 | C29: =Supuestos!$D$7 -> 6000 | D29: =Supuestos!$D$7 -> 6000 | E29: =Supuestos!$D$7 -> 6000 | F29: =Supuestos!$D$7 -> 6000 | G29: =Supuestos!$D$7 -> 6000 | H29: =Supuestos!$D$7 -> 6000 | I29: =Supuestos!$D$7 -> 6000 | ... M29: =Supuestos!$D$7 -> 6000 | N29: =SUM(B29:M29) -> 72000
A30: Impresiones | B30: =B29/(Supuestos!$D$8*B28)*1000 -> 61381.074 | C30: =C29/(Supuestos!$D$8*C28)*1000 -> 56470.588 | D30: =D29/(Supuestos!$D$8*D28)*1000 -> 74303.406 | E30: =E29/(Supuestos!$D$8*E28)*1000 -> 70588.235 | F30: =F29/(Supuestos!$D$8*F28)*1000 -> 70588.235 | G30: =G29/(Supuestos!$D$8*G28)*1000 -> 70588.235 | H30: =H29/(Supuestos!$D$8*H28)*1000 -> 67226.891 | I30: =I29/(Supuestos!$D$8*I28)*1000 -> 70588.235 | ... M30: =M29/(Supuestos!$D$8*M28)*1000 -> 67226.891 | N30: =SUM(B30:M30) -> 824441.67
A31: Clics | B31: =B30*Supuestos!$D$9 -> 736.57289 | C31: =C30*Supuestos!$D$9 -> 677.64706 | D31: =D30*Supuestos!$D$9 -> 891.64087 | E31: =E30*Supuestos!$D$9 -> 847.05882 | F31: =F30*Supuestos!$D$9 -> 847.05882 | G31: =G30*Supuestos!$D$9 -> 847.05882 | H31: =H30*Supuestos!$D$9 -> 806.72269 | I31: =I30*Supuestos!$D$9 -> 847.05882 | ... M31: =M30*Supuestos!$D$9 -> 806.72269 | N31: =SUM(B31:M31) -> 9893.3
A32: Conversión efectiva | B32: =Supuestos!$D$10*B27 -> 0.018 | C32: =Supuestos!$D$10*C27 -> 0.0255 | D32: =Supuestos!$D$10*D27 -> 0.0105 | E32: =Supuestos!$D$10*E27 -> 0.01425 | F32: =Supuestos!$D$10*F27 -> 0.01275 | G32: =Supuestos!$D$10*G27 -> 0.0135 | H32: =Supuestos!$D$10*H27 -> 0.01725 | I32: =Supuestos!$D$10*I27 -> 0.015 | ... M32: =Supuestos!$D$10*M27 -> 0.01575
A33: Pedidos por anuncios | B33: =B31*B32 -> 13.258312 | C33: =C31*C32 -> 17.28 | D33: =D31*D32 -> 9.3622291 | E33: =E31*E32 -> 12.070588 | F33: =F31*F32 -> 10.8 | G33: =G31*G32 -> 11.435294 | H33: =H31*H32 -> 13.915966 | I33: =I31*I32 -> 12.705882 | ... M33: =M31*M32 -> 12.705882 | N33: =SUM(B33:M33) -> 148.37502
A34: Pedidos orgánicos | B34: =Supuestos!$D$5*4.345*(1+Supuestos!$D$6)^(B26-1)*B27 -> 46.926 | C34: =Supuestos!$D$5*4.345*(1+Supuestos!$D$6)^(C26-1)*C27 -> 68.472855 | D34: =Supuestos!$D$5*4.345*(1+Supuestos!$D$6)^(D26-1)*D27 -> 29.040546 | E34: =Supuestos!$D$5*4.345*(1+Supuestos!$D$6)^(E26-1)*E27 -> 40.594535 | F34: =Supuestos!$D$5*4.345*(1+Supuestos!$D$6)^(F26-1)*F27 -> 37.411069 | G34: =Supuestos!$D$5*4.345*(1+Supuestos!$D$6)^(G26-1)*G27 -> 40.800071 | H34: =Supuestos!$D$5*4.345*(1+Supuestos!$D$6)^(H26-1)*H27 -> 53.697427 | I34: =Supuestos!$D$5*4.345*(1+Supuestos!$D$6)^(I26-1)*I27 -> 48.094218 | ... M34: =Supuestos!$D$5*4.345*(1+Supuestos!$D$6)^(M26-1)*M27 -> 56.836989 | N34: =SUM(B34:M34) -> 559.97803
A35: Pedidos minoristas totales | B35: =B33+B34 -> 60.184312 | C35: =C33+C34 -> 85.752855 | D35: =D33+D34 -> 38.402775 | E35: =E33+E34 -> 52.665123 | F35: =F33+F34 -> 48.211069 | G35: =G33+G34 -> 52.235366 | H35: =H33+H34 -> 67.613394 | I35: =I33+I34 -> 60.8001 | ... M35: =M33+M34 -> 69.542871 | N35: =SUM(B35:M35) -> 708.35306
A36: Ventas minoristas con IVA (MXN) | B36: =B35*Supuestos!$D$11 -> 22870.039 | C36: =C35*Supuestos!$D$11 -> 32586.085 | D36: =D35*Supuestos!$D$11 -> 14593.055 | E36: =E35*Supuestos!$D$11 -> 20012.747 | F36: =F35*Supuestos!$D$11 -> 18320.206 | G36: =G35*Supuestos!$D$11 -> 19849.439 | H36: =H35*Supuestos!$D$11 -> 25693.09 | I36: =I35*Supuestos!$D$11 -> 23104.038 | ... M36: =M35*Supuestos!$D$11 -> 26426.291 | N36: =SUM(B36:M36) -> 269174.16
A37: Ventas minoristas netas, sin IVA (MXN) | B37: =B36/(1+Supuestos!$C$23*Supuestos!$C$24) -> 19715.55 | C37: =C36/(1+Supuestos!$C$23*Supuestos!$C$24) -> 28091.452 | D37: =D36/(1+Supuestos!$C$23*Supuestos!$C$24) -> 12580.219 | E37: =E36/(1+Supuestos!$C$23*Supuestos!$C$24) -> 17252.368 | F37: =F36/(1+Supuestos!$C$23*Supuestos!$C$24) -> 15793.281 | G37: =G36/(1+Supuestos!$C$23*Supuestos!$C$24) -> 17111.585 | H37: =H36/(1+Supuestos!$C$23*Supuestos!$C$24) -> 22149.215 | I37: =I36/(1+Supuestos!$C$23*Supuestos!$C$24) -> 19917.274 | ... M37: =M36/(1+Supuestos!$C$23*Supuestos!$C$24) -> 22781.285 | N37: =SUM(B37:M37) -> 232046.69
A38: Cuentas mayoristas nuevas | B38: =IF(B26>=Supuestos!$C$21,Supuestos!$D$14,0) -> 0 | C38: =IF(C26>=Supuestos!$C$21,Supuestos!$D$14,0) -> 0 | D38: =IF(D26>=Supuestos!$C$21,Supuestos!$D$14,0) -> 2 | E38: =IF(E26>=Supuestos!$C$21,Supuestos!$D$14,0) -> 2 | F38: =IF(F26>=Supuestos!$C$21,Supuestos!$D$14,0) -> 2 | G38: =IF(G26>=Supuestos!$C$21,Supuestos!$D$14,0) -> 2 | H38: =IF(H26>=Supuestos!$C$21,Supuestos!$D$14,0) -> 2 | I38: =IF(I26>=Supuestos!$C$21,Supuestos!$D$14,0) -> 2 | ... M38: =IF(M26>=Supuestos!$C$21,Supuestos!$D$14,0) -> 2 | N38: =SUM(B38:M38) -> 20
A39: Cuentas mayoristas activas | B39: =B38 -> 0 | C39: =B39*Supuestos!$D$15+C38 -> 0 | D39: =C39*Supuestos!$D$15+D38 -> 2 | E39: =D39*Supuestos!$D$15+E38 -> 3.86 | F39: =E39*Supuestos!$D$15+F38 -> 5.5898 | G39: =F39*Supuestos!$D$15+G38 -> 7.198514 | H39: =G39*Supuestos!$D$15+H38 -> 8.694618 | I39: =H39*Supuestos!$D$15+I38 -> 10.085995 | J39: =I39*Supuestos!$D$15+J38 -> 11.379975 | ... M39: =L39*Supuestos!$D$15+M38 -> 14.743363 | N39: =M39 -> 14.743363
A40: Pedidos de mayoreo | B40: =B39*Supuestos!$D$16*B27 -> 0 | C40: =C39*Supuestos!$D$16*C27 -> 0 | D40: =D39*Supuestos!$D$16*D27 -> 0.7 | E40: =E39*Supuestos!$D$16*E27 -> 1.8335 | F40: =F39*Supuestos!$D$16*F27 -> 2.375665 | G40: =G39*Supuestos!$D$16*G27 -> 3.2393313 | H40: =H39*Supuestos!$D$16*H27 -> 4.9994054 | I40: =I39*Supuestos!$D$16*I27 -> 5.0429974 | ... M40: =M39*Supuestos!$D$16*M27 -> 7.7402654 | N40: =SUM(B40:M40) -> 42.996944
A41: Ventas de mayoreo, sin IVA (MXN) | B41: =B40*Supuestos!$D$17 -> 0 | C41: =C40*Supuestos!$D$17 -> 0 | D41: =D40*Supuestos!$D$17 -> 1680 | E41: =E40*Supuestos!$D$17 -> 4400.4 | F41: =F40*Supuestos!$D$17 -> 5701.596 | G41: =G40*Supuestos!$D$17 -> 7774.3951 | H41: =H40*Supuestos!$D$17 -> 11998.573 | I41: =I40*Supuestos!$D$17 -> 12103.194 | ... M41: =M40*Supuestos!$D$17 -> 18576.637 | N41: =SUM(B41:M41) -> 103192.67
A42: VENTAS NETAS TOTALES (MXN) | B42: =B37+B41 -> 19715.55 | C42: =C37+C41 -> 28091.452 | D42: =D37+D41 -> 14260.219 | E42: =E37+E41 -> 21652.768 | F42: =F37+F41 -> 21494.877 | G42: =G37+G41 -> 24885.98 | H42: =H37+H41 -> 34147.788 | I42: =I37+I41 -> 32020.468 | ... M42: =M37+M41 -> 41357.922 | N42: =SUM(B42:M42) -> 335239.36
...

Sheet Costos
A1: Costo por unidad: producir tú o tercerizar
A2: Costos de referencia: el filamento sale del precio de Creality México; el resto son SUPUESTOS. Pesa tus piezas, mide tus minutos y pide cotizaciones, y sustituye las celdas azules.
A4: Producto | B4: Precio público | C4: Precio neto minorista | D4: Precio mayoreo neto | E4: PLA (g) | F4: Otros materiales | G4: Mano de obra | H4: Máquina y energía | I4: Empaque | J4: COSTO PROPIO | K4: Maquila ÷ costo propio | L4: COSTO TERCERIZADO | M4: Decisión | N4: COSTO USADO | O4: Margen minorista | P4: Margen mayoreo | Q4: Unid./año cons. | R4: Unid./año base | S4: Unid./año optim. | T4: Descuento máximo de mayoreo
A5: =Supuestos!A54 -> Fichas de lotería sueltas | B5: =Supuestos!B54 -> 5 | C5: =B5/(1+Supuestos!$C$23*Supuestos!$C$24) -> 4.3103448 | D5: =B5*(1-Supuestos!$C$22) -> 2.9 | E5: 3 | F5: 0 | G5: 0.42 | H5: 0.3 | I5: 0.1 | J5: =E5*Supuestos!$C$31/1000+F5+G5+H5+I5 -> 1.867 | K5: 1.35 | L5: =J5*K5*(1+Supuestos!$C$32) -> 2.6464725 | M5: =Tercerizar!$J$5 -> Producir | N5: =IF(M5="Producir",J5,L5) -> 1.867 | O5: =(C5-N5)/C5 -> 0.566856 | P5: =(D5-N5)/D5 -> 0.3562069 | Q5: =(Demanda!$N$17*Supuestos!$C54/Supuestos!$C$67/$C5+Demanda!$N$21*Supuestos!$D54/Supuestos!$D$67/$D5) -> 1292.2908 | R5: =(Demanda!$N$37*Supuestos!$C54/Supuestos!$C$67/$C5+Demanda!$N$41*Supuestos!$D54/Supuestos!$D$67/$D5) -> 4094.6606 | S5: =(Demanda!$N$57*Supuestos!$C54/Supuestos!$C$67/$C5+Demanda!$N$61*Supuestos!$D54/Supuestos!$D$67/$D5) -> 11838.825 | T5: =MAX(0,1-(N5*Supuestos!$D$18/(1-Supuestos!$C$36))/B5) -> 0.50213333
A6: =Supuestos!A55 -> Paquete de 25 fichas | B6: =Supuestos!B55 -> 70 | C6: =B6/(1+Supuestos!$C$23*Supuestos!$C$24) -> 60.344828 | D6: =B6*(1-Supuestos!$C$22) -> 40.6 | E6: =25*E5 -> 75 | F6: 4 | G6: =25*G5+2 -> 12.5 | H6: =25*H5 -> 7.5 | I6: 1 | J6: =E6*Supuestos!$C$31/1000+F6+G6+H6+I6 -> 51.175 | K6: 1.35 | L6: =J6*K6*(1+Supuestos!$C$32) -> 72.540562 | M6: =Tercerizar!$J$5 -> Producir | N6: =IF(M6="Producir",J6,L6) -> 51.175 | O6: =(C6-N6)/C6 -> 0.15195714 | P6: =(D6-N6)/D6 -> -0.26046798 | Q6: =(Demanda!$N$17*Supuestos!$C55/Supuestos!$C$67/$C6+Demanda!$N$21*Supuestos!$D55/Supuestos!$D$67/$D6) -> 307.5041 | R6: =(Demanda!$N$37*Supuestos!$C55/Supuestos!$C$67/$C6+Demanda!$N$41*Supuestos!$D55/Supuestos!$D$67/$D6) -> 1048.9008 | S6: =(Demanda!$N$57*Supuestos!$C55/Supuestos!$C$67/$C6+Demanda!$N$61*Supuestos!$D55/Supuestos!$D$67/$D6) -> 3190.5004 | T6: =MAX(0,1-(N6*Supuestos!$D$18/(1-Supuestos!$C$36))/B6) -> 0.025238095
A7: =Supuestos!A56 -> Paquete de 50 fichas | B7: =Supuestos!B56 -> 135 | C7: =B7/(1+Supuestos!$C$23*Supuestos!$C$24) -> 116.37931 | D7: =B7*(1-Supuestos!$C$22) -> 78.3 | E7: =50*E5 -> 150 | F7: 6 | G7: =50*G5+2 -> 23 | H7: =50*H5 -> 15 | I7: 1 | J7: =E7*Supuestos!$C$31/1000+F7+G7+H7+I7 -> 97.35 | K7: 1.35 | L7: =J7*K7*(1+Supuestos!$C$32) -> 137.99363 | M7: =Tercerizar!$J$5 -> Producir | N7: =IF(M7="Producir",J7,L7) -> 97.35 | O7: =(C7-N7)/C7 -> 0.16351111 | P7: =(D7-N7)/D7 -> -0.24329502 | Q7: =(Demanda!$N$17*Supuestos!$C56/Supuestos!$C$67/$C7+Demanda!$N$21*Supuestos!$D56/Supuestos!$D$67/$D7) -> 135.54391 | R7: =(Demanda!$N$37*Supuestos!$C56/Supuestos!$C$67/$C7+Demanda!$N$41*Supuestos!$D56/Supuestos!$D$67/$D7) -> 456.53919 | S7: =(Demanda!$N$57*Supuestos!$C56/Supuestos!$C$67/$C7+Demanda!$N$61*Supuestos!$D56/Supuestos!$D$67/$D7) -> 1377.271 | T7: =MAX(0,1-(N7*Supuestos!$D$18/(1-Supuestos!$C$36))/B7) -> 0.038518519
A8: =Supuestos!A57 -> Paquete de 100 fichas | B8: =Supuestos!B57 -> 280 | C8: =B8/(1+Supuestos!$C$23*Supuestos!$C$24) -> 241.37931 | D8: =B8*(1-Supuestos!$C$22) -> 162.4 | E8: =100*E5 -> 300 | F8: 10 | G8: =100*G5+2 -> 44 | H8: =100*H5 -> 30 | I8: 1 | J8: =E8*Supuestos!$C$31/1000+F8+G8+H8+I8 -> 189.7 | K8: 1.35 | L8: =J8*K8*(1+Supuestos!$C$32) -> 268.89975 | M8: =Tercerizar!$J$5 -> Producir | N8: =IF(M8="Producir",J8,L8) -> 189.7 | O8: =(C8-N8)/C8 -> 0.2141 | P8: =(D8-N8)/D8 -> -0.16810345 | Q8: =(Demanda!$N$17*Supuestos!$C57/Supuestos!$C$67/$C8+Demanda!$N$21*Supuestos!$D57/Supuestos!$D$67/$D8) -> 49.976324 | R8: =(Demanda!$N$37*Supuestos!$C57/Supuestos!$C$67/$C8+Demanda!$N$41*Supuestos!$D57/Supuestos!$D$67/$D8) -> 167.67207 | S8: =(Demanda!$N$57*Supuestos!$C57/Supuestos!$C$67/$C8+Demanda!$N$61*Supuestos!$D57/Supuestos!$D$67/$D8) -> 504.51635 | T8: =MAX(0,1-(N8*Supuestos!$D$18/(1-Supuestos!$C$36))/B8) -> 0.096666667
A9: =Supuestos!A58 -> Tazas personalizadas | B9: =Supuestos!B58 -> 198 | C9: =B9/(1+Supuestos!$C$23*Supuestos!$C$24) -> 170.68966 | D9: =B9*(1-Supuestos!$C$22) -> 114.84 | E9: 0 | F9: 42 | G9: 3.5 | H9: 1.5 | I9: 5 | J9: =E9*Supuestos!$C$31/1000+F9+G9+H9+I9 -> 52 | K9: 1.5 | L9: =J9*K9*(1+Supuestos!$C$32) -> 81.9 | M9: =Tercerizar!$J$7 -> Tercerizar | N9: =IF(M9="Producir",J9,L9) -> 81.9 | O9: =(C9-N9)/C9 -> 0.52018182 | P9: =(D9-N9)/D9 -> 0.28683386 | Q9: =(Demanda!$N$17*Supuestos!$C58/Supuestos!$C$67/$C9+Demanda!$N$21*Supuestos!$D58/Supuestos!$D$67/$D9) -> 47.904295 | R9: =(Demanda!$N$37*Supuestos!$C58/Supuestos!$C$67/$C9+Demanda!$N$41*Supuestos!$D58/Supuestos!$D$67/$D9) -> 134.91482 | S9: =(Demanda!$N$57*Supuestos!$C58/Supuestos!$C$67/$C9+Demanda!$N$61*Supuestos!$D58/Supuestos!$D$67/$D9) -> 354.36585 | T9: =MAX(0,1-(N9*Supuestos!$D$18/(1-Supuestos!$C$36))/B9) -> 0.44848485
A10: =Supuestos!A59 -> Vasos y termos personalizados | B10: =Supuestos!B59 -> 497 | C10: =B10/(1+Supuestos!$C$23*Supuestos!$C$24) -> 428.44828 | D10: =B10*(1-Supuestos!$C$22) -> 288.26 | E10: 0 | F10: 170 | G10: 4.2 | H10: 6 | I10: 8 | J10: =E10*Supuestos!$C$31/1000+F10+G10+H10+I10 -> 188.2 | K10: 1.35 | L10: =J10*K10*(1+Supuestos!$C$32) -> 266.7735 | M10: =Tercerizar!$J$6 -> Tercerizar | N10: =IF(M10="Producir",J10,L10) -> 266.7735 | O10: =(C10-N10)/C10 -> 0.37734958 | P10: =(D10-N10)/D10 -> 0.074538611 | Q10: =(Demanda!$N$17*Supuestos!$C59/Supuestos!$C$67/$C10+Demanda!$N$21*Supuestos!$D59/Supuestos!$D$67/$D10) -> 22.558782 | R10: =(Demanda!$N$37*Supuestos!$C59/Supuestos!$C$67/$C10+Demanda!$N$41*Supuestos!$D59/Supuestos!$D$67/$D10) -> 61.816181 | S10: =(Demanda!$N$57*Supuestos!$C59/Supuestos!$C$67/$C10+Demanda!$N$61*Supuestos!$D59/Supuestos!$D$67/$D10) -> 158.27683 | T10: =MAX(0,1-(N10*Supuestos!$D$18/(1-Supuestos!$C$36))/B10) -> 0.28430986
A11: =Supuestos!A60 -> Agendas | B11: =Supuestos!B60 -> 397 | C11: =B11/(1+Supuestos!$C$23*Supuestos!$C$24) -> 342.24138 | D11: =B11*(1-Supuestos!$C$22) -> 230.26 | E11: 0 | F11: 160 | G11: 8.4 | H11: 0 | I11: 6 | J11: =E11*Supuestos!$C$31/1000+F11+G11+H11+I11 -> 174.4 | K11: 1.15 | L11: =J11*K11*(1+Supuestos!$C$32) -> 210.588 | M11: =Tercerizar!$J$8 -> Producir | N11: =IF(M11="Producir",J11,L11) -> 174.4 | O11: =(C11-N11)/C11 -> 0.49041814 | P11: =(D11-N11)/D11 -> 0.24259533 | Q11: =(Demanda!$N$17*Supuestos!$C60/Supuestos!$C$67/$C11+Demanda!$N$21*Supuestos!$D60/Supuestos!$D$67/$D11) -> 24.974263 | R11: =(Demanda!$N$37*Supuestos!$C60/Supuestos!$C$67/$C11+Demanda!$N$41*Supuestos!$D60/Supuestos!$D$67/$D11) -> 71.769064 | S11: =(Demanda!$N$57*Supuestos!$C60/Supuestos!$C$67/$C11+Demanda!$N$61*Supuestos!$D60/Supuestos!$D$67/$D11) -> 191.92044 | T11: =MAX(0,1-(N11*Supuestos!$D$18/(1-Supuestos!$C$36))/B11) -> 0.41427372
A12: =Supuestos!A61 -> Libretas | B12: =Supuestos!B61 -> 250 | C12: =B12/(1+Supuestos!$C$23*Supuestos!$C$24) -> 215.51724 | D12: =B12*(1-Supuestos!$C$22) -> 145 | E12: 0 | F12: 70 | G12: 5.6 | H12: 8 | I12: 4 | J12: =E12*Supuestos!$C$31/1000+F12+G12+H12+I12 -> 87.6 | K12: 1.15 | L12: =J12*K12*(1+Supuestos!$C$32) -> 105.777 | M12: =Tercerizar!$J$8 -> Producir | N12: =IF(M12="Producir",J12,L12) -> 87.6 | O12: =(C12-N12)/C12 -> 0.593536 | P12: =(D12-N12)/D12 -> 0.39586207 | Q12: =(Demanda!$N$17*Supuestos!$C61/Supuestos!$C$67/$C12+Demanda!$N$21*Supuestos!$D61/Supuestos!$D$67/$D12) -> 35.315395 | R12: =(Demanda!$N$37*Supuestos!$C61/Supuestos!$C$67/$C12+Demanda!$N$41*Supuestos!$D61/Supuestos!$D$67/$D12) -> 114.8208 | S12: =(Demanda!$N$57*Supuestos!$C61/Supuestos!$C$67/$C12+Demanda!$N$61*Supuestos!$D61/Supuestos!$D$67/$D12) -> 338.16648 | T12: =MAX(0,1-(N12*Supuestos!$D$18/(1-Supuestos!$C$36))/B12) -> 0.5328
A13: =Supuestos!A62 -> Sellos (madera, autoentintables y cera) | B13: =Supuestos!B62 -> 424 | C13: =B13/(1+Supuestos!$C$23*Supuestos!$C$24) -> 365.51724 | D13: =B13*(1-Supuestos!$C$22) -> 245.92 | E13: 0 | F13: 110 | G13: 7 | H13: 12 | I13: 5 | J13: =E13*Supuestos!$C$31/1000+F13+G13+H13+I13 -> 134 | K13: 1.2 | L13: =J13*K13*(1+Supuestos!$C$32) -> 168.84 | M13: =Tercerizar!$J$6 -> Tercerizar | N13: =IF(M13="Producir",J13,L13) -> 168.84 | O13: =(C13-N13)/C13 -> 0.53807925 | P13: =(D13-N13)/D13 -> 0.31343526 | Q13: =(Demanda!$N$17*Supuestos!$C62/Supuestos!$C$67/$C13+Demanda!$N$21*Supuestos!$D62/Supuestos!$D$67/$D13) -> 30.994438 | R13: =(Demanda!$N$37*Supuestos!$C62/Supuestos!$C$67/$C13+Demanda!$N$41*Supuestos!$D62/Supuestos!$D$67/$D13) -> 95.006093 | S13: =(Demanda!$N$57*Supuestos!$C62/Supuestos!$C$67/$C13+Demanda!$N$61*Supuestos!$D62/Supuestos!$D$67/$D13) -> 267.91477 | T13: =MAX(0,1-(N13*Supuestos!$D$18/(1-Supuestos!$C$36))/B13) -> 0.4690566
A14: =Supuestos!A63 -> Impresión 3D y otros personalizados | B14: =Supuestos!B63 -> 600 | C14: =B14/(1+Supuestos!$C$23*Supuestos!$C$24) -> 517.24138 | D14: =B14*(1-Supuestos!$C$22) -> 348 | E14: 0 | F14: 150 | G14: 40 | H14: 15 | I14: 15 | J14: =E14*Supuestos!$C$31/1000+F14+G14+H14+I14 -> 220 | K14: 1.4 | L14: =J14*K14*(1+Supuestos!$C$32) -> 323.4 | M14: =Tercerizar!$J$5 -> Producir | N14: =IF(M14="Producir",J14,L14) -> 220 | O14: =(C14-N14)/C14 -> 0.57466667 | P14: =(D14-N14)/D14 -> 0.36781609 | Q14: =(Demanda!$N$17*Supuestos!$C63/Supuestos!$C$67/$C14+Demanda!$N$21*Supuestos!$D63/Supuestos!$D$67/$D14) -> 7.1879883 | R14: =(Demanda!$N$37*Supuestos!$C63/Supuestos!$C$67/$C14+Demanda!$N$41*Supuestos!$D63/Supuestos!$D$67/$D14) -> 19.295639 | S14: =(Demanda!$N$57*Supuestos!$C63/Supuestos!$C$67/$C14+Demanda!$N$61*Supuestos!$D63/Supuestos!$D$67/$D14) -> 48.423737 | T14: =MAX(0,1-(N14*Supuestos!$D$18/(1-Supuestos!$C$36))/B14) -> 0.51111111
A15: =Supuestos!A64 -> Mini CD con NFC | B15: =Supuestos!B64 -> 185 | C15: =B15/(1+Supuestos!$C$23*Supuestos!$C$24) -> 159.48276 | D15: =B15*(1-Supuestos!$C$22) -> 107.3 | E15: 0 | F15: 36 | G15: 3.5 | H15: 4 | I15: 4 | J15: =E15*Supuestos!$C$31/1000+F15+G15+H15+I15 -> 47.5 | K15: 1.3 | L15: =J15*K15*(1+Supuestos!$C$32) -> 64.8375 | M15: =Tercerizar!$J$8 -> Producir | N15: =IF(M15="Producir",J15,L15) -> 47.5 | O15: =(C15-N15)/C15 -> 0.70216216 | P15: =(D15-N15)/D15 -> 0.55731594 | Q15: =(Demanda!$N$17*Supuestos!$C64/Supuestos!$C$67/$C15+Demanda!$N$21*Supuestos!$D64/Supuestos!$D$67/$D15) -> 48.905852 | R15: =(Demanda!$N$37*Supuestos!$C64/Supuestos!$C$67/$C15+Demanda!$N$41*Supuestos!$D64/Supuestos!$D$67/$D15) -> 151.57394 | S15: =(Demanda!$N$57*Supuestos!$C64/Supuestos!$C$67/$C15+Demanda!$N$61*Supuestos!$D64/Supuestos!$D$67/$D15) -> 431.07689 | T15: =MAX(0,1-(N15*Supuestos!$D$18/(1-Supuestos!$C$36))/B15) -> 0.65765766
A16: =Supuestos!A65 -> Colección Pride | B16: =Supuestos!B65 -> 269 | C16: =B16/(1+Supuestos!$C$23*Supuestos!$C$24) -> 231.89655 | D16: =B16*(1-Supuestos!$C$22) -> 156.02 | E16: 0 | F16: 120 | G16: 8 | H16: 12 | I16: 12 | J16: =E16*Supuestos!$C$31/1000+F16+G16+H16+I16 -> 152 | K16: 1.2 | L16: =J16*K16*(1+Supuestos!$C$32) -> 191.52 | M16: =Tercerizar!$J$7 -> Tercerizar | N16: =IF(M16="Producir",J16,L16) -> 191.52 | O16: =(C16-N16)/C16 -> 0.1741145 | P16: =(D16-N16)/D16 -> -0.22753493 | Q16: =(Demanda!$N$17*Supuestos!$C65/Supuestos!$C$67/$C16+Demanda!$N$21*Supuestos!$D65/Supuestos!$D$67/$D16) -> 28.028447 | R16: =(Demanda!$N$37*Supuestos!$C65/Supuestos!$C$67/$C16+Demanda!$N$41*Supuestos!$D65/Supuestos!$D$67/$D16) -> 86.868582 | S16: =(Demanda!$N$57*Supuestos!$C65/Supuestos!$C$67/$C16+Demanda!$N$61*Supuestos!$D65/Supuestos!$D$67/$D16) -> 247.0546 | T16: =MAX(0,1-(N16*Supuestos!$D$18/(1-Supuestos!$C$36))/B16) -> 0.05070632
A17: =Supuestos!A66 -> Kits y regalos de temporada | B17: =Supuestos!B66 -> 900 | C17: =B17/(1+Supuestos!$C$23*Supuestos!$C$24) -> 775.86207 | D17: =B17*(1-Supuestos!$C$22) -> 522 | E17: 0 | F17: 280 | G17: 40 | H17: 10 | I17: 40 | J17: =E17*Supuestos!$C$31/1000+F17+G17+H17+I17 -> 370 | K17: 1.25 | L17: =J17*K17*(1+Supuestos!$C$32) -> 485.625 | M17: =Tercerizar!$J$8 -> Producir | N17: =IF(M17="Producir",J17,L17) -> 370 | O17: =(C17-N17)/C17 -> 0.52311111 | P17: =(D17-N17)/D17 -> 0.29118774 | Q17: =(Demanda!$N$17*Supuestos!$C66/Supuestos!$C$67/$C17+Demanda!$N$21*Supuestos!$D66/Supuestos!$D$67/$D17) -> 10.538945 | R17: =(Demanda!$N$37*Supuestos!$C66/Supuestos!$C$67/$C17+Demanda!$N$41*Supuestos!$D66/Supuestos!$D$67/$D17) -> 29.68126 | S17: =(Demanda!$N$57*Supuestos!$C66/Supuestos!$C$67/$C17+Demanda!$N$61*Supuestos!$D66/Supuestos!$D$67/$D17) -> 77.960487 | T17: =MAX(0,1-(N17*Supuestos!$D$18/(1-Supuestos!$C$36))/B17) -> 0.45185185
A19: Costo ÷ precio neto, minorista (todos los productos) | B19: =SUMPRODUCT(Supuestos!C54:C66,N5:N17/C5:C17)/Supuestos!C67 -> 0.5914722
A20: Costo ÷ precio neto, mayoreo (todos los productos) | B20: =SUMPRODUCT(Supuestos!D54:D66,N5:N17/D5:D17)/Supuestos!D67 -> 1.0227915
A22: Margen negativo = vendes por debajo de tu costo. Revisa sobre todo los paquetes de fichas a precio de mayoreo: el descuento de 40% a 50% puede dejarlos en pérdida con estos costos.

Sheet Tercerizar
A1: ¿Producir tú o tercerizar? · caso base
A2: Compara el costo anual de producir (variable + equipo) con el de pagar maquila. Si el volumen no cubre el equipo, conviene tercerizar. Los precios de maquila son SUPUESTOS hasta que cotices.
A4: Grupo de producción | B4: Productos | C4: Unidades por año | D4: Costo variable propio | E4: Costo de tercerizar | F4: Equipo (costo) | G4: Costo fijo anual | H4: Costo total de producir | I4: Ahorro si tercerizas | J4: Recomendación | K4: Punto de equilibrio (unid./año)
A5: 3D | B5: Impresión 3D (fichas, paquetes y piezas a medida) | C5: =Costos!R5+Costos!R6+Costos!R7+Costos!R8+Costos!R14 -> 5787.0683 | D5: =Costos!R5*Costos!J5*Supuestos!$D$18+Costos!R6*Costos!J6*Supuestos!$D$18+Costos!R7*Costos!J7*Supuestos!$D$18+Costos!R8*Costos!J8*Supuestos!$D$18+Costos!R14*Costos!J14*Supuestos!$D$18 -> 141818.75 | E5: =Costos!R5*Costos!L5*Supuestos!$D$18+Costos!R6*Costos!L6*Supuestos!$D$18+Costos!R7*Costos!L7*Supuestos!$D$18+Costos!R8*Costos!L8*Supuestos!$D$18+Costos!R14*Costos!L14*Supuestos!$D$18 -> 201250.94 | F5: =Inversión!D5 -> 36000 | G5: =F5/Supuestos!$C$27+F5*Supuestos!$C$34 -> 15600 | H5: =D5+G5 -> 157418.75 | I5: =H5-E5 -> -43832.193 | J5: =IF(H5<=E5,"Producir","Tercerizar") -> Producir | K5: =IF(E5/C5>D5/C5,G5/(E5/C5-D5/C5),"n/a") -> 1519.0128
A6: Láser | B6: Láser (vasos, termos y sellos) | C6: =Costos!R10+Costos!R13 -> 156.82227 | D6: =Costos!R10*Costos!J10*Supuestos!$D$18+Costos!R13*Costos!J13*Supuestos!$D$18 -> 24364.622 | E6: =Costos!R10*Costos!L10*Supuestos!$D$18+Costos!R13*Costos!L13*Supuestos!$D$18 -> 32531.748 | F6: =Inversión!D6 -> 60000 | G6: =F6/Supuestos!$C$27+F6*Supuestos!$C$34 -> 26000 | H6: =D6+G6 -> 50364.622 | I6: =H6-E6 -> 17832.874 | J6: =IF(H6<=E6,"Producir","Tercerizar") -> Tercerizar | K6: =IF(E6/C6>D6/C6,G6/(E6/C6-D6/C6),"n/a") -> 499.24283
A7: Sublimación | B7: Sublimación (tazas y Colección Pride) | C7: =Costos!R9+Costos!R16 -> 221.7834 | D7: =Costos!R9*Costos!J9*Supuestos!$D$18+Costos!R16*Costos!J16*Supuestos!$D$18 -> 20219.595 | E7: =Costos!R9*Costos!L9*Supuestos!$D$18+Costos!R16*Costos!L16*Supuestos!$D$18 -> 27686.595 | F7: =Inversión!D7 -> 18000 | G7: =F7/Supuestos!$C$27+F7*Supuestos!$C$34 -> 7800 | H7: =D7+G7 -> 28019.595 | I7: =H7-E7 -> 333.00051 | J7: =IF(H7<=E7,"Producir","Tercerizar") -> Tercerizar | K7: =IF(E7/C7>D7/C7,G7/(E7/C7-D7/C7),"n/a") -> 231.67412
A8: Herramientas | B8: Libretas, agendas, Mini CD y kits | C8: =Costos!R11+Costos!R12+Costos!R15+Costos!R17 -> 367.84506 | D8: =Costos!R11*Costos!J11*Supuestos!$D$18+Costos!R12*Costos!J12*Supuestos!$D$18+Costos!R15*Costos!J15*Supuestos!$D$18+Costos!R17*Costos!J17*Supuestos!$D$18 -> 40756.655 | E8: =Costos!R11*Costos!L11*Supuestos!$D$18+Costos!R12*Costos!L12*Supuestos!$D$18+Costos!R15*Costos!L15*Supuestos!$D$18+Costos!R17*Costos!L17*Supuestos!$D$18 -> 51500.741 | F8: =Inversión!D8 -> 10000 | G8: =F8/Supuestos!$C$27+F8*Supuestos!$C$34 -> 4333.3333 | H8: =D8+G8 -> 45089.989 | I8: =H8-E8 -> -6410.7521 | J8: =IF(H8<=E8,"Producir","Tercerizar") -> Producir | K8: =IF(E8/C8>D8/C8,G8/(E8/C8-D8/C8),"n/a") -> 148.36026
A10: Ahorro positivo = tercerizar cuesta menos que producir. El punto de equilibrio es el volumen anual a partir del cual producir sale más barato.
A11: La recomendación decide el costo usado en las hojas Costos, Resultados e Inversión. Para forzar otra decisión, cambia las fórmulas de la columna Decisión en la hoja Costos.
A13: Lectura cualitativa (no está en los números)
A14: • Calidad y marca: las fichas son tu producto insignia y llevan acabado a mano. Tercerizarlas expone el diseño y el control de calidad.
A15: • Propiedad intelectual: varios diseños reproducen marcas de terceros. Un maquilador serio puede negarse a fabricarlos sin licencia.
A16: • Capacidad: producir te limita a las horas de tus impresoras; tercerizar permite absorber el pico de diciembre sin comprar equipo.
A17: • Caja: tercerizar convierte la inversión en equipo en costo variable y reduce el capital inicial, a cambio de menos margen.
A18: • Recomendación práctica: producir tú lo que da identidad (fichas y paquetes) y comprar insumo para personalizar o tercerizar lo que es commodity (blancos de tazas, vasos, libretas, agendas).

Sheet Inversión
A1: Inversión inicial
A2: El equipo solo cuenta si la hoja Tercerizar recomienda producir ese grupo. Los precios del equipo son SUPUESTOS: pide cotizaciones.
A4: Equipo | B4: Cantidad | C4: Costo unitario (MXN) | D4: Costo total (MXN) | E4: Grupo | F4: ¿Se compra? | G4: Nota
A5: Impresoras 3D (cantidad según capacidad) | B5: =MAX(1,ROUNDUP((Costos!R5*1+Costos!R6*25+Costos!R7*50+Costos!R8*100)*Supuestos!$C$35/Supuestos!$C$33+Costos!R14*2/Supuestos!$C$33,0)) -> 4 | C5: 9000 | D5: =B5*C5 -> 36000 | E5: 3D | F5: =IF(Tercerizar!$J$5="Producir","Sí","No") -> Sí | G5: SUPUESTO de precio. La cantidad sale de las fichas del caso base × horas por ficha ÷ horas por impresora.
A6: Grabadora láser (vasos, termos y sellos) | B6: 1 | C6: 60000 | D6: =B6*C6 -> 60000 | E6: Láser | F6: =IF(Tercerizar!$J$6="Producir","Sí","No") -> No | G6: SUPUESTO. Cotiza láser de fibra o diodo según material.
A7: Equipo de sublimación (prensa, impresora y papel inicial) | B7: 1 | C7: 18000 | D7: =B7*C7 -> 18000 | E7: Sublimación | F7: =IF(Tercerizar!$J$7="Producir","Sí","No") -> No | G7: SUPUESTO.
A8: Herramientas, mesas de trabajo y empaque | B8: 1 | C8: 10000 | D8: =B8*C8 -> 10000 | E8: Herramientas | F8: =IF(Tercerizar!$J$8="Producir","Sí","No") -> Sí | G8: SUPUESTO.
A9: Registro de marca, fotografía y diseño de marca | B9: 1 | C9: 10000 | D9: =B9*C9 -> 10000 | F9: Sí | G9: SUPUESTO. Conviene proteger la marca antes de escalar.
A10: Equipo e inversión inicial incluidos (MXN) | D10: =SUMPRODUCT((F5:F9="Sí")*D5:D9) -> 56000
A12: Necesidad total de inversión | D12: Conservador | E12: Base | F12: Optimista | G12: Nota
A13: Equipo e inversión inicial (de arriba) | D13: =Inversión!$D$10 -> 56000 | E13: =Inversión!$D$10 -> 56000 | F13: =Inversión!$D$10 -> 56000 | G13: Solo lo que recomienda producir la hoja Tercerizar.
A14: Capital de trabajo (costos de operación de N meses) | D14: =Supuestos!$C$28*(Resultados!N9+Resultados!N10+Resultados!N13+Resultados!N14+Resultados!N15)/12 -> 35354.065 | E14: =Supuestos!$C$28*(Resultados!N33+Resultados!N34+Resultados!N37+Resultados!N38+Resultados!N39)/12 -> 66260.119 | F14: =Supuestos!$C$28*(Resultados!N57+Resultados!N58+Resultados!N61+Resultados!N62+Resultados!N63)/12 -> 139807.51 | G14: Producción, comisiones, anuncios y gastos fijos.
A15: INVERSIÓN TOTAL NECESARIA (MXN) | D15: =D13+D14 -> 91354.065 | E15: =E13+E14 -> 122260.12 | F15: =F13+F14 -> 195807.51
A16: Utilidad neta anual · RESICO (MXN) | D16: =Resultados!N19 -> -120538.5 | E16: =Resultados!N43 -> -84573.649 | F16: =Resultados!N67 -> 58202.762
A17: Recuperación de la inversión (meses) | D17: =IF(D16>0,D15/(D16/12),"No se recupera") -> No se recupera | E17: =IF(E16>0,E15/(E16/12),"No se recupera") -> No se recupera | F17: =IF(F16>0,F15/(F16/12),"No se recupera") -> 40.370767 | G17: Inversión total ÷ utilidad neta mensual promedio.
A18: Retorno sobre la inversión del primer año | D18: =IFERROR(D16/D15,0) -> -1.3194651 | E18: =IFERROR(E16/E15,0) -> -0.69175173 | F18: =IFERROR(F16/F15,0) -> 0.29724479

Sheet Resultados
A1: Estado de resultados mensual
A2: ISR RESICO: tasa sobre ingresos cobrados sin IVA (1.0% a 2.5%, hasta $3.5 millones al año). Persona moral: 30% sobre utilidad y PTU de 10%. Confirma tu régimen con tu contador.
A4: ESCENARIO CONSERVADOR
A5: Concepto | B5: Nov 2026 | C5: Dic 2026 | D5: Ene 2027 | E5: Feb 2027 | F5: Mar 2027 | G5: Abr 2027 | H5: May 2027 | I5: Jun 2027 | J5: Jul 2027 | K5: Ago 2027 | L5: Sep 2027 | M5: Oct 2027 | N5: Total 12 meses
A6: Ventas minoristas netas | B6: =Demanda!B17 -> 8029.1236 | C6: =Demanda!C17 -> 11381.569 | D6: =Demanda!D17 -> 4870.8169 | E6: =Demanda!E17 -> 6628.3479 | F6: =Demanda!F17 -> 5983.112 | G6: =Demanda!G17 -> 6391.1878 | H6: =Demanda!H17 -> 8195.0072 | I6: =Demanda!I17 -> 7227.9259 | ... M6: =Demanda!M17 -> 7823.1394 | N6: =SUM(B6:M6) -> 86441.756
A7: Ventas de mayoreo netas | B7: =Demanda!B21 -> 0 | C7: =Demanda!C21 -> 0 | D7: =Demanda!D21 -> 441 | E7: =Demanda!E21 -> 1137.15 | F7: =Demanda!F21 -> 1451.205 | G7: =Demanda!G21 -> 1949.913 | H7: =Demanda!H21 -> 2966.8999 | I7: =Demanda!I21 -> 2951.9217 | ... M7: =Demanda!M21 -> 4308.4921 | N7: =SUM(B7:M7) -> 24924.467
A8: VENTAS NETAS | B8: =B6+B7 -> 8029.1236 | C8: =C6+C7 -> 11381.569 | D8: =D6+D7 -> 5311.8169 | E8: =E6+E7 -> 7765.4979 | F8: =F6+F7 -> 7434.317 | G8: =G6+G7 -> 8341.1008 | H8: =H6+H7 -> 11161.907 | I8: =I6+I7 -> 10179.848 | ... M8: =M6+M7 -> 12131.632 | N8: =SUM(B8:M8) -> 111366.22
A9: Costo de producción minorista | B9: =B6*Costos!$B$19*Supuestos!$C$18 -> 5461.354 | C9: =C6*Costos!$B$19*Supuestos!$C$18 -> 7741.6641 | D9: =D6*Costos!$B$19*Supuestos!$C$18 -> 3313.0958 | E9: =E6*Costos!$B$19*Supuestos!$C$18 -> 4508.5561 | F9: =F6*Costos!$B$19*Supuestos!$C$18 -> 4069.6711 | G9: =G6*Costos!$B$19*Supuestos!$C$18 -> 4347.2414 | H9: =H6*Costos!$B$19*Supuestos!$C$18 -> 5574.1868 | I9: =I6*Costos!$B$19*Supuestos!$C$18 -> 4916.3849 | ... M9: =M6*Costos!$B$19*Supuestos!$C$18 -> 5321.245 | N9: =SUM(B9:M9) -> 58797.08
A10: Costo de producción mayoreo | B10: =B7*Costos!$B$20*Supuestos!$C$18 -> 0 | C10: =C7*Costos!$B$20*Supuestos!$C$18 -> 0 | D10: =D7*Costos!$B$20*Supuestos!$C$18 -> 518.70871 | E10: =E7*Costos!$B$20*Supuestos!$C$18 -> 1337.5275 | F10: =F7*Costos!$B$20*Supuestos!$C$18 -> 1706.9222 | G10: =G7*Costos!$B$20*Supuestos!$C$18 -> 2293.5076 | H10: =H7*Costos!$B$20*Supuestos!$C$18 -> 3489.698 | I10: =I7*Costos!$B$20*Supuestos!$C$18 -> 3472.0805 | ... M10: =M7*Costos!$B$20*Supuestos!$C$18 -> 5067.6925 | N10: =SUM(B10:M10) -> 29316.413
A11: UTILIDAD BRUTA | B11: =B8-B9-B10 -> 2567.7697 | C11: =C8-C9-C10 -> 3639.9051 | D11: =D8-D9-D10 -> 1480.0125 | E11: =E8-E9-E10 -> 1919.4144 | F11: =F8-F9-F10 -> 1657.7237 | G11: =G8-G9-G10 -> 1700.3518 | H11: =H8-H9-H10 -> 2098.0223 | I11: =I8-I9-I10 -> 1791.3823 | ... M11: =M8-M9-M10 -> 1742.6941 | N11: =SUM(B11:M11) -> 23252.73
A12: Margen bruto | B12: =IFERROR(B11/B8,0) -> 0.31980697 | C12: =IFERROR(C11/C8,0) -> 0.31980697 | D12: =IFERROR(D11/D8,0) -> 0.27862641 | E12: =IFERROR(E11/E8,0) -> 0.24717209 | F12: =IFERROR(F11/F8,0) -> 0.22298265 | G12: =IFERROR(G11/G8,0) -> 0.2038522 | H12: =IFERROR(H11/H8,0) -> 0.18796271 | I12: =IFERROR(I11/I8,0) -> 0.17597339 | ... N12: =IFERROR(N11/N8,0) -> 0.20879517
A13: Comisiones de pasarela y marketplace | B13: =Demanda!B16*Supuestos!$C$25 -> 372.55134 | C13: =Demanda!C16*Supuestos!$C$25 -> 528.10481 | D13: =Demanda!D16*Supuestos!$C$25 -> 226.00591 | E13: =Demanda!E16*Supuestos!$C$25 -> 307.55534 | F13: =Demanda!F16*Supuestos!$C$25 -> 277.6164 | G13: =Demanda!G16*Supuestos!$C$25 -> 296.55111 | H13: =Demanda!H16*Supuestos!$C$25 -> 380.24834 | I13: =Demanda!I16*Supuestos!$C$25 -> 335.37576 | ... M13: =Demanda!M16*Supuestos!$C$25 -> 362.99367 | N13: =SUM(B13:M13) -> 4010.8975
A14: Anuncios | B14: =Demanda!B9 -> 4000 | C14: =Demanda!C9 -> 4000 | D14: =Demanda!D9 -> 4000 | E14: =Demanda!E9 -> 4000 | F14: =Demanda!F9 -> 4000 | G14: =Demanda!G9 -> 4000 | H14: =Demanda!H9 -> 4000 | I14: =Demanda!I9 -> 4000 | ... M14: =Demanda!M9 -> 4000 | N14: =SUM(B14:M14) -> 48000
A15: Gastos fijos | B15: =Supuestos!$C$26 -> 6000 | C15: =Supuestos!$C$26 -> 6000 | D15: =Supuestos!$C$26 -> 6000 | E15: =Supuestos!$C$26 -> 6000 | F15: =Supuestos!$C$26 -> 6000 | G15: =Supuestos!$C$26 -> 6000 | H15: =Supuestos!$C$26 -> 6000 | I15: =Supuestos!$C$26 -> 6000 | ... M15: =Supuestos!$C$26 -> 6000 | N15: =SUM(B15:M15) -> 72000
A16: Depreciación del equipo | B16: =Inversión!$D$10/(Supuestos!$C$27*12) -> 1555.5556 | C16: =Inversión!$D$10/(Supuestos!$C$27*12) -> 1555.5556 | D16: =Inversión!$D$10/(Supuestos!$C$27*12) -> 1555.5556 | E16: =Inversión!$D$10/(Supuestos!$C$27*12) -> 1555.5556 | F16: =Inversión!$D$10/(Supuestos!$C$27*12) -> 1555.5556 | G16: =Inversión!$D$10/(Supuestos!$C$27*12) -> 1555.5556 | H16: =Inversión!$D$10/(Supuestos!$C$27*12) -> 1555.5556 | I16: =Inversión!$D$10/(Supuestos!$C$27*12) -> 1555.5556 | ... M16: =Inversión!$D$10/(Supuestos!$C$27*12) -> 1555.5556 | N16: =SUM(B16:M16) -> 18666.667
A17: UTILIDAD OPERATIVA (antes de impuestos) | B17: =B11-B13-B14-B15-B16 -> -9360.3372 | C17: =C11-C13-C14-C15-C16 -> -8443.7552 | D17: =D11-D13-D14-D15-D16 -> -10301.549 | E17: =E11-E13-E14-E15-E16 -> -9943.6965 | F17: =F11-F13-F14-F15-F16 -> -10175.448 | G17: =G11-G13-G14-G15-G16 -> -10151.755 | H17: =H11-H13-H14-H15-H16 -> -9837.7816 | I17: =I11-I13-I14-I15-I16 -> -10099.549 | ... M17: =M11-M13-M14-M15-M16 -> -10175.855 | N17: =SUM(B17:M17) -> -119424.83
A18: ISR RESICO (persona física) | B18: =B8*IF(B8<=25000,0.01,IF(B8<=50000,0.011,IF(B8<=83333.33,0.015,IF(B8<=208333.33,0.02,0.025)))) -> 80.291236 | C18: =C8*IF(C8<=25000,0.01,IF(C8<=50000,0.011,IF(C8<=83333.33,0.015,IF(C8<=208333.33,0.02,0.025)))) -> 113.81569 | D18: =D8*IF(D8<=25000,0.01,IF(D8<=50000,0.011,IF(D8<=83333.33,0.015,IF(D8<=208333.33,0.02,0.025)))) -> 53.118169 | E18: =E8*IF(E8<=25000,0.01,IF(E8<=50000,0.011,IF(E8<=83333.33,0.015,IF(E8<=208333.33,0.02,0.025)))) -> 77.654979 | F18: =F8*IF(F8<=25000,0.01,IF(F8<=50000,0.011,IF(F8<=83333.33,0.015,IF(F8<=208333.33,0.02,0.025)))) -> 74.34317 | G18: =G8*IF(G8<=25000,0.01,IF(G8<=50000,0.011,IF(G8<=83333.33,0.015,IF(G8<=208333.33,0.02,0.025)))) -> 83.411008 | H18: =H8*IF(H8<=25000,0.01,IF(H8<=50000,0.011,IF(H8<=83333.33,0.015,IF(H8<=208333.33,0.02,0.025)))) -> 111.61907 | I18: =I8*IF(I8<=25000,0.01,IF(I8<=50000,0.011,IF(I8<=83333.33,0.015,IF(I8<=208333.33,0.02,0.025)))) -> 101.79848 | ... M18: =M8*IF(M8<=25000,0.01,IF(M8<=50000,0.011,IF(M8<=83333.33,0.015,IF(M8<=208333.33,0.02,0.025)))) -> 121.31632 | N18: =SUM(B18:M18) -> 1113.6622
A19: UTILIDAD NETA · RESICO | B19: =B17-B18 -> -9440.6285 | C19: =C17-C18 -> -8557.5709 | D19: =D17-D18 -> -10354.667 | E19: =E17-E18 -> -10021.352 | F19: =F17-F18 -> -10249.791 | G19: =G17-G18 -> -10235.166 | H19: =H17-H18 -> -9949.4007 | I19: =I17-I18 -> -10201.348 | ... M19: =M17-M18 -> -10297.171 | N19: =SUM(B19:M19) -> -120538.5
A20: ISR persona moral | B20: =MAX(0,B17)*Supuestos!$C$29 -> 0 | C20: =MAX(0,C17)*Supuestos!$C$29 -> 0 | D20: =MAX(0,D17)*Supuestos!$C$29 -> 0 | E20: =MAX(0,E17)*Supuestos!$C$29 -> 0 | F20: =MAX(0,F17)*Supuestos!$C$29 -> 0 | G20: =MAX(0,G17)*Supuestos!$C$29 -> 0 | H20: =MAX(0,H17)*Supuestos!$C$29 -> 0 | I20: =MAX(0,I17)*Supuestos!$C$29 -> 0 | ... M20: =MAX(0,M17)*Supuestos!$C$29 -> 0 | N20: =SUM(B20:M20) -> 0
A21: PTU | B21: =MAX(0,B17)*Supuestos!$C$30 -> 0 | C21: =MAX(0,C17)*Supuestos!$C$30 -> 0 | D21: =MAX(0,D17)*Supuestos!$C$30 -> 0 | E21: =MAX(0,E17)*Supuestos!$C$30 -> 0 | F21: =MAX(0,F17)*Supuestos!$C$30 -> 0 | G21: =MAX(0,G17)*Supuestos!$C$30 -> 0 | H21: =MAX(0,H17)*Supuestos!$C$30 -> 0 | I21: =MAX(0,I17)*Supuestos!$C$30 -> 0 | ... M21: =MAX(0,M17)*Supuestos!$C$30 -> 0 | N21: =SUM(B21:M21) -> 0
A22: UTILIDAD NETA · persona moral | B22: =B17-B20-B21 -> -9360.3372 | C22: =C17-C20-C21 -> -8443.7552 | D22: =D17-D20-D21 -> -10301.549 | E22: =E17-E20-E21 -> -9943.6965 | F22: =F17-F20-F21 -> -10175.448 | G22: =G17-G20-G21 -> -10151.755 | H22: =H17-H20-H21 -> -9837.7816 | I22: =I17-I20-I21 -> -10099.549 | ... M22: =M17-M20-M21 -> -10175.855 | N22: =SUM(B22:M22) -> -119424.83
A23: Ingresos del año frente al límite RESICO ($3.5 millones) | N23: =IF(N8<=3500000,"Dentro del límite","Rebasa el límite") -> Dentro del límite
A24: Utilidad operativa acumulada | B24: =SUM($B17:B17) -> -9360.3372 | C24: =SUM($B17:C17) -> -17804.092 | D24: =SUM($B17:D17) -> -28105.641 | E24: =SUM($B17:E17) -> -38049.338 | F24: =SUM($B17:F17) -> -48224.786 | G24: =SUM($B17:G17) -> -58376.541 | H24: =SUM($B17:H17) -> -68214.323 | I24: =SUM($B17:I17) -> -78313.872 | ... M24: =SUM($B17:M17) -> -119424.83
A28: ESCENARIO BASE
A29: Concepto | B29: Nov 2026 | C29: Dic 2026 | D29: Ene 2027 | E29: Feb 2027 | F29: Mar 2027 | G29: Abr 2027 | H29: May 2027 | I29: Jun 2027 | J29: Jul 2027 | K29: Ago 2027 | L29: Sep 2027 | M29: Oct 2027 | N29: Total 12 meses
A30: Ventas minoristas netas | B30: =Demanda!B37 -> 19715.55 | C30: =Demanda!C37 -> 28091.452 | D30: =Demanda!D37 -> 12580.219 | E30: =Demanda!E37 -> 17252.368 | F30: =Demanda!F37 -> 15793.281 | G30: =Demanda!G37 -> 17111.585 | H30: =Demanda!H37 -> 22149.215 | I30: =Demanda!I37 -> 19917.274 | ... M30: =Demanda!M37 -> 22781.285 | N30: =SUM(B30:M30) -> 232046.69
A31: Ventas de mayoreo netas | B31: =Demanda!B41 -> 0 | C31: =Demanda!C41 -> 0 | D31: =Demanda!D41 -> 1680 | E31: =Demanda!E41 -> 4400.4 | F31: =Demanda!F41 -> 5701.596 | G31: =Demanda!G41 -> 7774.3951 | H31: =Demanda!H41 -> 11998.573 | I31: =Demanda!I41 -> 12103.194 | ... M31: =Demanda!M41 -> 18576.637 | N31: =SUM(B31:M31) -> 103192.67
A32: VENTAS NETAS | B32: =B30+B31 -> 19715.55 | C32: =C30+C31 -> 28091.452 | D32: =D30+D31 -> 14260.219 | E32: =E30+E31 -> 21652.768 | F32: =F30+F31 -> 21494.877 | G32: =G30+G31 -> 24885.98 | H32: =H30+H31 -> 34147.788 | I32: =I30+I31 -> 32020.468 | ... M32: =M30+M31 -> 41357.922 | N32: =SUM(B32:M32) -> 335239.36
A33: Costo de producción minorista | B33: =B30*Costos!$B$19*Supuestos!$D$18 -> 11661.2 | C33: =C30*Costos!$B$19*Supuestos!$D$18 -> 16615.313 | D33: =D30*Costos!$B$19*Supuestos!$D$18 -> 7440.8501 | E33: =E30*Costos!$B$19*Supuestos!$D$18 -> 10204.296 | F33: =F30*Costos!$B$19*Supuestos!$D$18 -> 9341.2868 | G33: =G30*Costos!$B$19*Supuestos!$D$18 -> 10121.027 | H33: =H30*Costos!$B$19*Supuestos!$D$18 -> 13100.645 | I33: =I30*Costos!$B$19*Supuestos!$D$18 -> 11780.514 | ... M33: =M30*Costos!$B$19*Supuestos!$D$18 -> 13474.497 | N33: =SUM(B33:M33) -> 137249.17
A34: Costo de producción mayoreo | B34: =B31*Costos!$B$20*Supuestos!$D$18 -> 0 | C34: =C31*Costos!$B$20*Supuestos!$D$18 -> 0 | D34: =D31*Costos!$B$20*Supuestos!$D$18 -> 1718.2897 | E34: =E31*Costos!$B$20*Supuestos!$D$18 -> 4500.6917 | F34: =F31*Costos!$B$20*Supuestos!$D$18 -> 5831.5439 | G34: =G31*Costos!$B$20*Supuestos!$D$18 -> 7951.5852 | H34: =H31*Costos!$B$20*Supuestos!$D$18 -> 12272.038 | I34: =I31*Costos!$B$20*Supuestos!$D$18 -> 12379.044 | ... M34: =M31*Costos!$B$20*Supuestos!$D$18 -> 19000.026 | N34: =SUM(B34:M34) -> 105544.58
A35: UTILIDAD BRUTA | B35: =B32-B33-B34 -> 8054.3504 | C35: =C32-C33-C34 -> 11476.139 | D35: =D32-D33-D34 -> 5101.0796 | E35: =E32-E33-E34 -> 6947.7801 | F35: =F32-F33-F34 -> 6322.0464 | G35: =G32-G33-G34 -> 6813.3681 | H35: =H32-H33-H34 -> 8775.1046 | I35: =I32-I33-I34 -> 7860.9102 | ... M35: =M32-M33-M34 -> 8883.3989 | N35: =SUM(B35:M35) -> 92445.608
A36: Margen bruto | B36: =IFERROR(B35/B32,0) -> 0.4085278 | C36: =IFERROR(C35/C32,0) -> 0.4085278 | D36: =IFERROR(D35/D32,0) -> 0.35771396 | E36: =IFERROR(E35/E32,0) -> 0.32087261 | F36: =IFERROR(F35/F32,0) -> 0.29411875 | G36: =IFERROR(G35/G32,0) -> 0.27378339 | H36: =IFERROR(H35/H32,0) -> 0.25697432 | I36: =IFERROR(I35/I32,0) -> 0.24549642 | ... N36: =IFERROR(N35/N32,0) -> 0.27576001
A37: Comisiones de pasarela y marketplace | B37: =Demanda!B36*Supuestos!$C$25 -> 914.80154 | C37: =Demanda!C36*Supuestos!$C$25 -> 1303.4434 | D37: =Demanda!D36*Supuestos!$C$25 -> 583.72218 | E37: =Demanda!E36*Supuestos!$C$25 -> 800.50987 | F37: =Demanda!F36*Supuestos!$C$25 -> 732.80824 | G37: =Demanda!G36*Supuestos!$C$25 -> 793.97756 | H37: =Demanda!H36*Supuestos!$C$25 -> 1027.7236 | I37: =Demanda!I36*Supuestos!$C$25 -> 924.16152 | ... M37: =Demanda!M36*Supuestos!$C$25 -> 1057.0516 | N37: =SUM(B37:M37) -> 10766.966
A38: Anuncios | B38: =Demanda!B29 -> 6000 | C38: =Demanda!C29 -> 6000 | D38: =Demanda!D29 -> 6000 | E38: =Demanda!E29 -> 6000 | F38: =Demanda!F29 -> 6000 | G38: =Demanda!G29 -> 6000 | H38: =Demanda!H29 -> 6000 | I38: =Demanda!I29 -> 6000 | ... M38: =Demanda!M29 -> 6000 | N38: =SUM(B38:M38) -> 72000
A39: Gastos fijos | B39: =Supuestos!$C$26 -> 6000 | C39: =Supuestos!$C$26 -> 6000 | D39: =Supuestos!$C$26 -> 6000 | E39: =Supuestos!$C$26 -> 6000 | F39: =Supuestos!$C$26 -> 6000 | G39: =Supuestos!$C$26 -> 6000 | H39: =Supuestos!$C$26 -> 6000 | I39: =Supuestos!$C$26 -> 6000 | ... M39: =Supuestos!$C$26 -> 6000 | N39: =SUM(B39:M39) -> 72000
